try:
    print(x)
except:
    print(" something went wrong")
finally:
    print("Thr try and exception is finished")
